2019-04-30 17:45:57,794 : INFO : Machine : Mission Pinball Framework Core Engine v0.53.0-dev.16
2019-04-30 17:45:57,795 : INFO : Machine : Command line arguments: {'no_load_cache': False, 'create_config_cache': True, 'bcp': True, 'configfile': ['config.yaml'], 'mpfconfigfile': 'c:\\users\\wilder\\appdata\\local\\programs\\python\\python36\\lib\\site-packages\\mpf\\mpfconfig.yaml', 'force_assets_load': False, 'jsonlogging': False, 'logfile': 'logs\\2019-04-30-17-45-57-mpf-RedTunic.log', 'pause': False, 'production': False, 'text_ui': True, 'loglevel': 10, 'consoleloglevel': 20, 'force_platform': None, 'syslog_address': None, 'mc_file_name': None, 'no_sound': False}
2019-04-30 17:45:57,795 : INFO : Machine : MPF path: c:\users\wilder\appdata\local\programs\python\python36\lib\site-packages\mpf
2019-04-30 17:45:57,795 : INFO : Machine : Machine path: C:\Users\Wilder\zelda
2019-04-30 17:45:57,795 : INFO : Machine : Platform: win32
2019-04-30 17:45:57,795 : INFO : Machine : Python executable location: c:\users\wilder\appdata\local\programs\python\python36\python.exe
2019-04-30 17:45:57,795 : INFO : Machine : Python version: 3.6.4 (64-bit)
2019-04-30 17:45:57,795 : INFO : Machine : Machine config file #1: config.yaml
2019-04-30 17:45:57,797 : INFO : ConfigProcessor : Loading config from cache: C:\Users\Wilder\AppData\Local\Temp\9bf880992bc5b85aa1bd2cc37b214e56.mpf_cache
2019-04-30 17:45:57,801 : DEBUG : asyncio : Using selector: SelectSelector
2019-04-30 17:45:57,802 : INFO : Machine : Initialise MPF.
2019-04-30 17:45:57,856 : DEBUG : FAST : Configuring FAST hardware.
2019-04-30 17:45:58,073 : INFO : FAST : Connecting to \\.\COM11 at 921600bps
2019-04-30 17:45:58,106 : INFO : FAST : Connected! Processor: NET, Board Type: FP-CPU-002-2, Firmware: 01.02
2019-04-30 17:45:58,107 : INFO : EventManager : Event: ======'machine_var_fast_net_firmware'====== Args={'value': '01.02', 'prev_value': None, 'change': True}
2019-04-30 17:45:58,107 : INFO : EventManager : Event: ======'machine_var_fast_net_model'====== Args={'value': 'FP-CPU-002-2', 'prev_value': None, 'change': True}
2019-04-30 17:45:58,107 : WARNING : FAST : Not resetting FAST NET because firmware is currently broken.
2019-04-30 17:45:58,170 : INFO : FAST : Connecting to \\.\COM12 at 921600bps
2019-04-30 17:45:58,219 : INFO : FAST : Connected! Processor: RGB, Board Type: FP-CPU-002-2, Firmware: 01.00
2019-04-30 17:45:58,219 : INFO : EventManager : Event: ======'machine_var_fast_rgb_firmware'====== Args={'value': '01.00', 'prev_value': None, 'change': True}
2019-04-30 17:45:58,219 : INFO : EventManager : Event: ======'machine_var_fast_rgb_model'====== Args={'value': 'FP-CPU-002-2', 'prev_value': None, 'change': True}
2019-04-30 17:45:58,220 : INFO : EventManager : Event: ======'machine_var_credits_string'====== Args={'value': 'FREE PLAY', 'prev_value': None, 'change': True}
2019-04-30 17:45:58,285 : DEBUG : YAML File Interface : Loading file: C:\Users\Wilder\zelda\data/machine_vars.yaml
2019-04-30 17:45:58,288 : INFO : EventManager : Event: ======'machine_var_player1_score'====== Args={'value': 5, 'prev_value': None, 'change': True}
2019-04-30 17:45:58,288 : INFO : EventManager : Event: ======'machine_var_mpf_version'====== Args={'value': 'MPF v0.53.0-dev.16', 'prev_value': None, 'change': True}
2019-04-30 17:45:58,288 : INFO : EventManager : Event: ======'machine_var_mpf_extended_version'====== Args={'value': 'MPF v0.53.0-dev.16, Config version:5, Show version: 5, BCP version:1.1', 'prev_value': None, 'change': True}
2019-04-30 17:45:58,288 : INFO : EventManager : Event: ======'machine_var_python_version'====== Args={'value': '3.6.4', 'prev_value': None, 'change': True}
2019-04-30 17:45:58,289 : INFO : EventManager : Event: ======'machine_var_platform'====== Args={'value': 'Windows-7-6.1.7601-SP1', 'prev_value': None, 'change': True}
2019-04-30 17:45:58,289 : INFO : EventManager : Event: ======'machine_var_platform_system'====== Args={'value': 'Windows', 'prev_value': None, 'change': True}
2019-04-30 17:45:58,289 : INFO : EventManager : Event: ======'machine_var_platform_release'====== Args={'value': '7', 'prev_value': None, 'change': True}
2019-04-30 17:45:58,289 : INFO : EventManager : Event: ======'machine_var_platform_version'====== Args={'value': '6.1.7601', 'prev_value': None, 'change': True}
2019-04-30 17:45:58,289 : INFO : EventManager : Event: ======'machine_var_platform_machine'====== Args={'value': 'AMD64', 'prev_value': None, 'change': True}
2019-04-30 17:45:58,289 : INFO : EventManager : Event: ======'init_phase_1'====== Args={}
2019-04-30 17:45:58,350 : INFO : ConfigProcessor : Loading config from cache: C:\Users\Wilder\AppData\Local\Temp\6fc1a42fdd0d487285862f5b943c745e.mpf_cache
2019-04-30 17:45:58,354 : DEBUG : ModeController : Loaded mode rupee_finder
2019-04-30 17:45:58,355 : INFO : ConfigProcessor : Loading config from cache: C:\Users\Wilder\AppData\Local\Temp\da675f6b180b79eecb40cb5eb7f75a18.mpf_cache
2019-04-30 17:45:58,358 : DEBUG : ModeController : Loaded mode bomb_finder
2019-04-30 17:45:58,359 : INFO : ConfigProcessor : Loading config from cache: C:\Users\Wilder\AppData\Local\Temp\6caaa2c03f737135abd403644138525e.mpf_cache
2019-04-30 17:45:58,363 : DEBUG : ModeController : Loaded mode shop
2019-04-30 17:45:58,364 : WARNING : ConfigProcessor : Config file in cache changed: C:\Users\Wilder\zelda\modes\ball_hold_tracker\config\ball_hold_tracker.yaml
2019-04-30 17:45:58,364 : INFO : ConfigProcessor : Loading config from file C:\Users\Wilder\zelda\modes\ball_hold_tracker\config\ball_hold_tracker.yaml.
2019-04-30 17:45:58,364 : DEBUG : YAML File Interface : Loading file: C:\Users\Wilder\zelda\modes\ball_hold_tracker\config\ball_hold_tracker.yaml
2019-04-30 17:45:58,387 : INFO : ConfigProcessor : Loading config: C:\Users\Wilder\zelda\modes\ball_hold_tracker\config\ball_hold_tracker.yaml
2019-04-30 17:45:58,388 : INFO : ConfigProcessor : Config file cache created: C:\Users\Wilder\AppData\Local\Temp\6fd2b5e36bbbd9c12f9ee3aa32f1ceca.mpf_cache
2019-04-30 17:45:58,391 : DEBUG : ModeController : Loaded mode ball_hold_tracker
2019-04-30 17:45:58,392 : INFO : ConfigProcessor : Loading config from cache: C:\Users\Wilder\AppData\Local\Temp\96294a9578657f44941f2a8ec647ae36.mpf_cache
2019-04-30 17:45:58,397 : DEBUG : ModeController : Loaded mode rupee3x_finder
2019-04-30 17:45:58,397 : INFO : ConfigProcessor : Loading config from cache: C:\Users\Wilder\AppData\Local\Temp\562f2c62ffb495bc414930beede29530.mpf_cache
2019-04-30 17:45:58,404 : DEBUG : ModeController : Loaded mode game_ender_mode
2019-04-30 17:45:58,404 : INFO : ConfigProcessor : Loading config from cache: C:\Users\Wilder\AppData\Local\Temp\43a06f52d0e9cf0597140b4c27159d40.mpf_cache
2019-04-30 17:45:58,408 : DEBUG : ModeController : Loaded mode escapehurryup
2019-04-30 17:45:58,408 : WARNING : ConfigProcessor : Config file in cache changed: C:\Users\Wilder\zelda\modes\ganon_battle\config\ganon_battle.yaml
2019-04-30 17:45:58,408 : INFO : ConfigProcessor : Loading config from file C:\Users\Wilder\zelda\modes\ganon_battle\config\ganon_battle.yaml.
2019-04-30 17:45:58,409 : DEBUG : YAML File Interface : Loading file: C:\Users\Wilder\zelda\modes\ganon_battle\config\ganon_battle.yaml
2019-04-30 17:45:58,648 : INFO : ConfigProcessor : Loading config: C:\Users\Wilder\zelda\modes\ganon_battle\config\ganon_battle.yaml
2019-04-30 17:45:58,649 : ERROR : asyncio : Exception in callback EventManager._async_handler_done(<QueuedEvent>)(<Task finishe...fig files.',)>) at c:\users\wilder\appdata\local\programs\python\python36\lib\site-packages\mpf\core\events.py:96
handle: <Handle EventManager._async_handler_done(<QueuedEvent>)(<Task finishe...fig files.',)>) at c:\users\wilder\appdata\local\programs\python\python36\lib\site-packages\mpf\core\events.py:96>
Traceback (most recent call last):
  File "c:\users\wilder\appdata\local\programs\python\python36\lib\site-packages\mpf\core\config_processor.py", line 145, in _load_config_file_and_return_loaded_files
    if config_type not in self.config_validator.get_config_spec()[k][
KeyError: 'queue_relay_event'

During handling of the above exception, another exception occurred:

Traceback (most recent call last):
  File "c:\users\wilder\appdata\local\programs\python\python36\lib\asyncio\events.py", line 145, in _run
    self._callback(*self._args)
  File "c:\users\wilder\appdata\local\programs\python\python36\lib\site-packages\mpf\core\events.py", line 99, in _async_handler_done
    future.result()
  File "c:\users\wilder\appdata\local\programs\python\python36\lib\site-packages\mpf\core\mode_controller.py", line 117, in load_modes
    self.machine.modes[mode] = self._load_mode(mode)
  File "c:\users\wilder\appdata\local\programs\python\python36\lib\site-packages\mpf\core\mode_controller.py", line 266, in _load_mode
    config = self._load_mode_config(mode_string)
  File "c:\users\wilder\appdata\local\programs\python\python36\lib\site-packages\mpf\core\mode_controller.py", line 184, in _load_mode_config
    store_to_cache=self.machine.options['create_config_cache'])
  File "c:\users\wilder\appdata\local\programs\python\python36\lib\site-packages\mpf\core\config_processor.py", line 112, in load_config_files_with_cache
    ignore_unknown_sections)
  File "c:\users\wilder\appdata\local\programs\python\python36\lib\site-packages\mpf\core\config_processor.py", line 154, in _load_config_file_and_return_loaded_files
    'files.'.format(k, filename, config_type))
ValueError: Found a "queue_relay_event:" section in config file C:\Users\Wilder\zelda\modes\ganon_battle\config\ganon_battle.yaml, but that section is not valid in mode config files.
2019-04-30 17:45:58,653 : INFO : Machine : Starting the main run loop.
2019-04-30 17:45:58,655 : INFO : Machine : Shutting down...
2019-04-30 17:45:58,655 : INFO : EventManager : Event: ======'shutdown'====== Args={}
2019-04-30 17:45:58,664 : ERROR : FAST : Stop called on serial connection \\.\COM12
2019-04-30 17:45:58,665 : ERROR : FAST : Stop called on serial connection \\.\COM11
2019-04-30 17:45:59,061 : ERROR : root : Found a "queue_relay_event:" section in config file C:\Users\Wilder\zelda\modes\ganon_battle\config\ganon_battle.yaml, but that section is not valid in mode config files.
Traceback (most recent call last):
  File "c:\users\wilder\appdata\local\programs\python\python36\lib\site-packages\mpf\core\config_processor.py", line 145, in _load_config_file_and_return_loaded_files
    if config_type not in self.config_validator.get_config_spec()[k][
KeyError: 'queue_relay_event'

During handling of the above exception, another exception occurred:

Traceback (most recent call last):
  File "c:\users\wilder\appdata\local\programs\python\python36\lib\site-packages\mpf\commands\game.py", line 220, in __init__
    MachineController(mpf_path, machine_path, vars(self.args)).run()
  File "c:\users\wilder\appdata\local\programs\python\python36\lib\site-packages\mpf\core\machine.py", line 716, in run
    self._run_loop()
  File "c:\users\wilder\appdata\local\programs\python\python36\lib\site-packages\mpf\core\machine.py", line 776, in _run_loop
    raise self._exception['exception']
  File "c:\users\wilder\appdata\local\programs\python\python36\lib\asyncio\events.py", line 145, in _run
    self._callback(*self._args)
  File "c:\users\wilder\appdata\local\programs\python\python36\lib\site-packages\mpf\core\events.py", line 99, in _async_handler_done
    future.result()
  File "c:\users\wilder\appdata\local\programs\python\python36\lib\site-packages\mpf\core\mode_controller.py", line 117, in load_modes
    self.machine.modes[mode] = self._load_mode(mode)
  File "c:\users\wilder\appdata\local\programs\python\python36\lib\site-packages\mpf\core\mode_controller.py", line 266, in _load_mode
    config = self._load_mode_config(mode_string)
  File "c:\users\wilder\appdata\local\programs\python\python36\lib\site-packages\mpf\core\mode_controller.py", line 184, in _load_mode_config
    store_to_cache=self.machine.options['create_config_cache'])
  File "c:\users\wilder\appdata\local\programs\python\python36\lib\site-packages\mpf\core\config_processor.py", line 112, in load_config_files_with_cache
    ignore_unknown_sections)
  File "c:\users\wilder\appdata\local\programs\python\python36\lib\site-packages\mpf\core\config_processor.py", line 154, in _load_config_file_and_return_loaded_files
    'files.'.format(k, filename, config_type))
ValueError: Found a "queue_relay_event:" section in config file C:\Users\Wilder\zelda\modes\ganon_battle\config\ganon_battle.yaml, but that section is not valid in mode config files.
