2019-05-28 21:21:20,079 : INFO : Machine : Mission Pinball Framework Core Engine v0.53.0-dev.16
2019-05-28 21:21:20,079 : INFO : Machine : Command line arguments: {'no_load_cache': False, 'create_config_cache': True, 'bcp': True, 'configfile': ['config.yaml'], 'mpfconfigfile': 'c:\\users\\wilder\\appdata\\local\\programs\\python\\python36\\lib\\site-packages\\mpf\\mpfconfig.yaml', 'force_assets_load': False, 'jsonlogging': False, 'logfile': 'logs\\2019-05-28-21-21-20-mpf-RedTunic.log', 'pause': False, 'production': False, 'text_ui': True, 'loglevel': 10, 'consoleloglevel': 20, 'force_platform': None, 'syslog_address': None, 'mc_file_name': None, 'no_sound': False}
2019-05-28 21:21:20,080 : INFO : Machine : MPF path: c:\users\wilder\appdata\local\programs\python\python36\lib\site-packages\mpf
2019-05-28 21:21:20,080 : INFO : Machine : Machine path: C:\Users\Wilder\zelda
2019-05-28 21:21:20,080 : INFO : Machine : Platform: win32
2019-05-28 21:21:20,080 : INFO : Machine : Python executable location: c:\users\wilder\appdata\local\programs\python\python36\python.exe
2019-05-28 21:21:20,080 : INFO : Machine : Python version: 3.6.4 (64-bit)
2019-05-28 21:21:20,080 : INFO : Machine : Machine config file #1: config.yaml
2019-05-28 21:21:20,083 : INFO : ConfigProcessor : Loading config from cache: C:\Users\Wilder\AppData\Local\Temp\9bf880992bc5b85aa1bd2cc37b214e56.mpf_cache
2019-05-28 21:21:20,128 : WARNING : ConfigProcessor : Config file in cache changed: C:\Users\Wilder\zelda\config\hardware.yaml
2019-05-28 21:21:20,128 : INFO : ConfigProcessor : Loading config from file c:\users\wilder\appdata\local\programs\python\python36\lib\site-packages\mpf\mpfconfig.yaml.
2019-05-28 21:21:20,129 : DEBUG : YAML File Interface : Loading file: c:\users\wilder\appdata\local\programs\python\python36\lib\site-packages\mpf\mpfconfig.yaml
2019-05-28 21:21:20,339 : INFO : ConfigProcessor : Loading config: c:\users\wilder\appdata\local\programs\python\python36\lib\site-packages\mpf\mpfconfig.yaml
2019-05-28 21:21:20,426 : INFO : ConfigProcessor : Loading config from file C:\Users\Wilder\zelda\config\config.yaml.
2019-05-28 21:21:20,426 : DEBUG : YAML File Interface : Loading file: C:\Users\Wilder\zelda\config\config.yaml
2019-05-28 21:21:20,534 : INFO : ConfigProcessor : Loading config: C:\Users\Wilder\zelda\config\config.yaml
2019-05-28 21:21:20,534 : DEBUG : YAML File Interface : Loading file: C:\Users\Wilder\zelda\config\hardware.yaml
2019-05-28 21:21:20,984 : ERROR : root : Error found in file C:\Users\Wilder\zelda\config\hardware.yaml: 'Key "default_source_device" was defined multiple times in config   in "C:\\Users\\Wilder\\zelda\\config\\hardware.yaml", line 19, column 9'
Traceback (most recent call last):
  File "c:\users\wilder\appdata\local\programs\python\python36\lib\site-packages\mpf\file_interfaces\yaml_interface.py", line 198, in load
    config = self.process(f)
  File "c:\users\wilder\appdata\local\programs\python\python36\lib\site-packages\mpf\file_interfaces\yaml_interface.py", line 224, in process
    return yaml.load(data_string, Loader=MpfLoader)
  File "c:\users\wilder\appdata\local\programs\python\python36\lib\site-packages\ruamel\yaml\main.py", line 639, in load
    return loader._constructor.get_single_data()  # type: ignore
  File "c:\users\wilder\appdata\local\programs\python\python36\lib\site-packages\ruamel\yaml\constructor.py", line 104, in get_single_data
    return self.construct_document(node)
  File "c:\users\wilder\appdata\local\programs\python\python36\lib\site-packages\ruamel\yaml\constructor.py", line 114, in construct_document
    for dummy in generator:
  File "c:\users\wilder\appdata\local\programs\python\python36\lib\site-packages\ruamel\yaml\constructor.py", line 611, in construct_yaml_map
    value = self.construct_mapping(node)
  File "c:\users\wilder\appdata\local\programs\python\python36\lib\site-packages\mpf\file_interfaces\yaml_interface.py", line 135, in construct_mapping
    format(key, key_node.start_mark))
KeyError: 'Key "default_source_device" was defined multiple times in config   in "C:\\Users\\Wilder\\zelda\\config\\hardware.yaml", line 19, column 9'

During handling of the above exception, another exception occurred:

Traceback (most recent call last):
  File "c:\users\wilder\appdata\local\programs\python\python36\lib\site-packages\mpf\commands\game.py", line 220, in __init__
    MachineController(mpf_path, machine_path, vars(self.args)).run()
  File "c:\users\wilder\appdata\local\programs\python\python36\lib\site-packages\mpf\core\machine.py", line 180, in __init__
    self._load_config()
  File "c:\users\wilder\appdata\local\programs\python\python36\lib\site-packages\mpf\core\machine.py", line 449, in _load_config
    store_to_cache=self.options['create_config_cache'])
  File "c:\users\wilder\appdata\local\programs\python\python36\lib\site-packages\mpf\core\config_processor.py", line 112, in load_config_files_with_cache
    ignore_unknown_sections)
  File "c:\users\wilder\appdata\local\programs\python\python36\lib\site-packages\mpf\core\config_processor.py", line 163, in _load_config_file_and_return_loaded_files
    subconfig, subsubfiles = self._load_config_file_and_return_loaded_files(full_file, config_type)
  File "c:\users\wilder\appdata\local\programs\python\python36\lib\site-packages\mpf\core\config_processor.py", line 132, in _load_config_file_and_return_loaded_files
    config = FileManager.load(filename, expected_version_str, True)
  File "c:\users\wilder\appdata\local\programs\python\python36\lib\site-packages\mpf\core\file_manager.py", line 99, in load
    return interface.load(file, verify_version, halt_on_error)
  File "c:\users\wilder\appdata\local\programs\python\python36\lib\site-packages\mpf\file_interfaces\yaml_interface.py", line 212, in load
    raise ValueError(msg)
ValueError: Error found in file C:\Users\Wilder\zelda\config\hardware.yaml: 'Key "default_source_device" was defined multiple times in config   in "C:\\Users\\Wilder\\zelda\\config\\hardware.yaml", line 19, column 9'
