2019-04-29 14:14:08,514 : kivy : Factory: 194 symbols loaded
2019-04-29 14:14:08,514 : kivy : Cache: register <kv.lang> with limit=None, timeout=None
2019-04-29 14:14:08,670 : kivy : Cache: register <kv.image> with limit=None, timeout=60
2019-04-29 14:14:08,670 : kivy : Cache: register <kv.atlas> with limit=None, timeout=None
2019-04-29 14:14:08,701 : kivy : Image: Providers: img_tex, img_dds, img_sdl2, img_pil, img_gif (img_ffpyplayer ignored)
2019-04-29 14:14:08,701 : kivy : Cache: register <kv.texture> with limit=1000, timeout=60
2019-04-29 14:14:08,701 : kivy : Cache: register <kv.shader> with limit=1000, timeout=3600
2019-04-29 14:14:08,763 : kivy : VideoGstplayer: Using Gstreamer 1.10.2.0
2019-04-29 14:14:08,763 : kivy : Video: Provider: gstplayer
2019-04-29 14:14:08,857 : kivy : Loading MPF-MC controller
2019-04-29 14:14:08,857 : mpfmc : Mission Pinball Framework Media Controller v0.53.0-dev.0
2019-04-29 14:14:08,857 : mpfmc : Mission Pinball Framework Game Engine v0.53.0-dev.16
2019-04-29 14:14:08,857 : mpfmc : Machine path: C:\Users\Wilder\zelda
2019-04-29 14:14:08,857 : ConfigProcessor : Config file in cache changed: C:\Users\Wilder\zelda\config\config
2019-04-29 14:14:08,857 : ConfigProcessor : Loading config from file c:\users\wilder\appdata\local\programs\python\python36\lib\site-packages\mpfmc\mcconfig.yaml.
2019-04-29 14:14:08,857 : YAML File Interface : Loading file: c:\users\wilder\appdata\local\programs\python\python36\lib\site-packages\mpfmc\mcconfig.yaml
2019-04-29 14:14:08,966 : ConfigProcessor : Loading config: c:\users\wilder\appdata\local\programs\python\python36\lib\site-packages\mpfmc\mcconfig.yaml
2019-04-29 14:14:08,982 : ConfigProcessor : Loading config from file C:\Users\Wilder\zelda\config\config.
2019-04-29 14:14:08,982 : YAML File Interface : Loading file: C:\Users\Wilder\zelda\config\config.yaml
2019-04-29 14:14:08,997 : kivy : YAML error found in file C:\Users\Wilder\zelda\config\config.yaml. Line 82,Position 1: while parsing a block mapping
  in "C:\Users\Wilder\zelda\config\config.yaml", line 3, column 1
expected <block end>, but found '-'
  in "C:\Users\Wilder\zelda\config\config.yaml", line 82, column 1
Traceback (most recent call last):
  File "c:\users\wilder\appdata\local\programs\python\python36\lib\site-packages\mpf\file_interfaces\yaml_interface.py", line 198, in load
    config = self.process(f)
  File "c:\users\wilder\appdata\local\programs\python\python36\lib\site-packages\mpf\file_interfaces\yaml_interface.py", line 224, in process
    return yaml.load(data_string, Loader=MpfLoader)
  File "c:\users\wilder\appdata\local\programs\python\python36\lib\site-packages\ruamel\yaml\main.py", line 639, in load
    return loader._constructor.get_single_data()  # type: ignore
  File "c:\users\wilder\appdata\local\programs\python\python36\lib\site-packages\ruamel\yaml\constructor.py", line 102, in get_single_data
    node = self.composer.get_single_node()
  File "c:\users\wilder\appdata\local\programs\python\python36\lib\site-packages\ruamel\yaml\composer.py", line 75, in get_single_node
    document = self.compose_document()
  File "c:\users\wilder\appdata\local\programs\python\python36\lib\site-packages\ruamel\yaml\composer.py", line 96, in compose_document
    node = self.compose_node(None, None)
  File "c:\users\wilder\appdata\local\programs\python\python36\lib\site-packages\ruamel\yaml\composer.py", line 132, in compose_node
    node = self.compose_mapping_node(anchor)
  File "c:\users\wilder\appdata\local\programs\python\python36\lib\site-packages\ruamel\yaml\composer.py", line 187, in compose_mapping_node
    while not self.parser.check_event(MappingEndEvent):
  File "c:\users\wilder\appdata\local\programs\python\python36\lib\site-packages\ruamel\yaml\parser.py", line 144, in check_event
    self.current_event = self.state()
  File "c:\users\wilder\appdata\local\programs\python\python36\lib\site-packages\ruamel\yaml\parser.py", line 561, in parse_block_mapping_key
    token.start_mark)
ruamel.yaml.parser.ParserError: while parsing a block mapping
  in "C:\Users\Wilder\zelda\config\config.yaml", line 3, column 1
expected <block end>, but found '-'
  in "C:\Users\Wilder\zelda\config\config.yaml", line 82, column 1

During handling of the above exception, another exception occurred:

Traceback (most recent call last):
  File "c:\users\wilder\appdata\local\programs\python\python36\lib\site-packages\mpfmc\commands\mc.py", line 209, in __init__
    thread_stopper=thread_stopper).run()
  File "c:\users\wilder\appdata\local\programs\python\python36\lib\site-packages\mpfmc\core\mc.py", line 97, in __init__
    self.machine_config = self._load_config()
  File "c:\users\wilder\appdata\local\programs\python\python36\lib\site-packages\mpfmc\core\mc.py", line 223, in _load_config
    mpf_config = self.mpf_config_processor.load_config_files_with_cache(files, "machine", True)
  File "c:\users\wilder\appdata\local\programs\python\python36\lib\site-packages\mpf\core\config_processor.py", line 112, in load_config_files_with_cache
    ignore_unknown_sections)
  File "c:\users\wilder\appdata\local\programs\python\python36\lib\site-packages\mpf\core\config_processor.py", line 132, in _load_config_file_and_return_loaded_files
    config = FileManager.load(filename, expected_version_str, True)
  File "c:\users\wilder\appdata\local\programs\python\python36\lib\site-packages\mpf\core\file_manager.py", line 99, in load
    return interface.load(file, verify_version, halt_on_error)
  File "c:\users\wilder\appdata\local\programs\python\python36\lib\site-packages\mpf\file_interfaces\yaml_interface.py", line 205, in load
    raise ValueError(msg)
ValueError: YAML error found in file C:\Users\Wilder\zelda\config\config.yaml. Line 82,Position 1: while parsing a block mapping
  in "C:\Users\Wilder\zelda\config\config.yaml", line 3, column 1
expected <block end>, but found '-'
  in "C:\Users\Wilder\zelda\config\config.yaml", line 82, column 1
2019-04-29 14:14:08,997 : kivy : Stopping child threads... (0 remaining)
2019-04-29 14:14:08,997 : kivy : All child threads stopped.
