2019-04-02 19:10:17,511 : INFO : Machine : Mission Pinball Framework Core Engine v0.52.1
2019-04-02 19:10:17,513 : INFO : Machine : Command line arguments: {'no_load_cache': False, 'create_config_cache': True, 'bcp': True, 'configfile': ['config.yaml'], 'mpfconfigfile': 'c:\\users\\wilder\\appdata\\local\\programs\\python\\python36\\lib\\site-packages\\mpf\\mpfconfig.yaml', 'force_assets_load': False, 'jsonlogging': False, 'logfile': 'logs\\2019-04-02-19-10-17-mpf-RedTunic.log', 'pause': False, 'production': False, 'text_ui': True, 'loglevel': 10, 'consoleloglevel': 20, 'force_platform': None, 'syslog_address': None, 'mc_file_name': None, 'no_sound': False}
2019-04-02 19:10:17,513 : INFO : Machine : MPF path: c:\users\wilder\appdata\local\programs\python\python36\lib\site-packages\mpf
2019-04-02 19:10:17,513 : INFO : Machine : Machine path: C:\Users\Wilder\zelda
2019-04-02 19:10:17,513 : INFO : Machine : Platform: win32
2019-04-02 19:10:17,513 : INFO : Machine : Python executable location: c:\users\wilder\appdata\local\programs\python\python36\python.exe
2019-04-02 19:10:17,513 : INFO : Machine : Python version: 3.6.4 (64-bit)
2019-04-02 19:10:17,514 : INFO : Machine : Machine config file #1: config.yaml
2019-04-02 19:10:17,516 : INFO : ConfigProcessor : Loading config from cache: C:\Users\Wilder\AppData\Local\Temp\9bf880992bc5b85aa1bd2cc37b214e56.mpf_cache
2019-04-02 19:10:17,520 : DEBUG : asyncio : Using selector: SelectSelector
2019-04-02 19:10:17,521 : INFO : Machine : Initialise MPF.
2019-04-02 19:10:17,574 : DEBUG : FAST : Configuring FAST hardware.
2019-04-02 19:10:17,801 : INFO : FAST : Connecting to \\.\COM11 at 921600bps
2019-04-02 19:10:17,834 : INFO : FAST : Connected! Processor: NET, Board Type: FP-CPU-002-2, Firmware: 01.02
2019-04-02 19:10:17,835 : INFO : EventManager : Event: ======'machine_var_fast_net_firmware'====== Args={'value': '01.02', 'prev_value': None, 'change': True}
2019-04-02 19:10:17,835 : INFO : EventManager : Event: ======'machine_var_fast_net_model'====== Args={'value': 'FP-CPU-002-2', 'prev_value': None, 'change': True}
2019-04-02 19:10:17,835 : WARNING : FAST : Not resetting FAST NET because firmware is currently broken.
2019-04-02 19:10:17,898 : INFO : FAST : Connecting to \\.\COM12 at 921600bps
2019-04-02 19:10:17,946 : INFO : FAST : Connected! Processor: RGB, Board Type: FP-CPU-002-2, Firmware: 01.00
2019-04-02 19:10:17,947 : INFO : EventManager : Event: ======'machine_var_fast_rgb_firmware'====== Args={'value': '01.00', 'prev_value': None, 'change': True}
2019-04-02 19:10:17,947 : INFO : EventManager : Event: ======'machine_var_fast_rgb_model'====== Args={'value': 'FP-CPU-002-2', 'prev_value': None, 'change': True}
2019-04-02 19:10:17,948 : INFO : EventManager : Event: ======'machine_var_credits_string'====== Args={'value': 'FREE PLAY', 'prev_value': None, 'change': True}
2019-04-02 19:10:18,030 : DEBUG : YAML File Interface : Loading file: C:\Users\Wilder\zelda\data/machine_vars.yaml
2019-04-02 19:10:18,033 : INFO : EventManager : Event: ======'machine_var_player1_score'====== Args={'value': 5, 'prev_value': None, 'change': True}
2019-04-02 19:10:18,034 : INFO : EventManager : Event: ======'machine_var_mpf_version'====== Args={'value': 'MPF v0.52.1', 'prev_value': None, 'change': True}
2019-04-02 19:10:18,034 : INFO : EventManager : Event: ======'machine_var_mpf_extended_version'====== Args={'value': 'MPF v0.52.1, Config version:5, Show version: 5, BCP version:1.1', 'prev_value': None, 'change': True}
2019-04-02 19:10:18,034 : INFO : EventManager : Event: ======'machine_var_python_version'====== Args={'value': '3.6.4', 'prev_value': None, 'change': True}
2019-04-02 19:10:18,035 : INFO : EventManager : Event: ======'machine_var_platform'====== Args={'value': 'Windows-7-6.1.7601-SP1', 'prev_value': None, 'change': True}
2019-04-02 19:10:18,035 : INFO : EventManager : Event: ======'machine_var_platform_system'====== Args={'value': 'Windows', 'prev_value': None, 'change': True}
2019-04-02 19:10:18,035 : INFO : EventManager : Event: ======'machine_var_platform_release'====== Args={'value': '7', 'prev_value': None, 'change': True}
2019-04-02 19:10:18,035 : INFO : EventManager : Event: ======'machine_var_platform_version'====== Args={'value': '6.1.7601', 'prev_value': None, 'change': True}
2019-04-02 19:10:18,035 : INFO : EventManager : Event: ======'machine_var_platform_machine'====== Args={'value': 'AMD64', 'prev_value': None, 'change': True}
2019-04-02 19:10:18,035 : INFO : EventManager : Event: ======'init_phase_1'====== Args={}
2019-04-02 19:10:18,101 : WARNING : ConfigProcessor : Config file in cache changed: C:\Users\Wilder\zelda\modes\lost_woods\config\lost_woods.yaml
2019-04-02 19:10:18,102 : INFO : ConfigProcessor : Loading config from file C:\Users\Wilder\zelda\modes\lost_woods\config\lost_woods.yaml.
2019-04-02 19:10:18,102 : DEBUG : YAML File Interface : Loading file: C:\Users\Wilder\zelda\modes\lost_woods\config\lost_woods.yaml
2019-04-02 19:10:18,254 : INFO : ConfigProcessor : Loading config: C:\Users\Wilder\zelda\modes\lost_woods\config\lost_woods.yaml
2019-04-02 19:10:18,256 : INFO : ConfigProcessor : Config file cache created: C:\Users\Wilder\AppData\Local\Temp\58a9cd5447353eacedab412f1c10b0ab.mpf_cache
2019-04-02 19:10:18,261 : DEBUG : ModeController : Loaded mode lost_woods
2019-04-02 19:10:18,262 : WARNING : ConfigProcessor : Config file in cache changed: C:\Users\Wilder\zelda\modes\slide_tracker\config\slide_tracker.yaml
2019-04-02 19:10:18,262 : INFO : ConfigProcessor : Loading config from file C:\Users\Wilder\zelda\modes\slide_tracker\config\slide_tracker.yaml.
2019-04-02 19:10:18,262 : DEBUG : YAML File Interface : Loading file: C:\Users\Wilder\zelda\modes\slide_tracker\config\slide_tracker.yaml
2019-04-02 19:10:18,310 : INFO : ConfigProcessor : Loading config: C:\Users\Wilder\zelda\modes\slide_tracker\config\slide_tracker.yaml
2019-04-02 19:10:18,311 : INFO : ConfigProcessor : Config file cache created: C:\Users\Wilder\AppData\Local\Temp\dbd150f896646081271b7a77a791f2fa.mpf_cache
2019-04-02 19:10:18,314 : DEBUG : ModeController : Loaded mode slide_tracker
2019-04-02 19:10:18,315 : INFO : ConfigProcessor : Loading config from cache: C:\Users\Wilder\AppData\Local\Temp\4afc9f23ca6340163a8bb51d7deea78f.mpf_cache
2019-04-02 19:10:18,318 : DEBUG : ModeController : Loaded mode base
2019-04-02 19:10:18,318 : INFO : ConfigProcessor : Loading config from cache: C:\Users\Wilder\AppData\Local\Temp\dd39e2de39eb354a1ec99be2f3167765.mpf_cache
2019-04-02 19:10:18,322 : DEBUG : ModeController : Loaded mode heartmeter
2019-04-02 19:10:18,322 : INFO : ConfigProcessor : Loading config from cache: C:\Users\Wilder\AppData\Local\Temp\86e0d165ea95889c95b56598c3ebe263.mpf_cache
2019-04-02 19:10:18,326 : DEBUG : ModeController : Loaded mode music_player
2019-04-02 19:10:18,326 : INFO : ConfigProcessor : Loading config from cache: C:\Users\Wilder\AppData\Local\Temp\cb8b20150020107be74f23a2ee427f56.mpf_cache
2019-04-02 19:10:18,334 : DEBUG : ModeController : Loaded mode high_score
2019-04-02 19:10:18,335 : INFO : ConfigProcessor : Loading config from cache: C:\Users\Wilder\AppData\Local\Temp\58664c35241624b07b13025a5964d2a4.mpf_cache
2019-04-02 19:10:18,340 : DEBUG : ModeController : Loaded mode video_player
2019-04-02 19:10:18,340 : WARNING : ConfigProcessor : Config file in cache changed: C:\Users\Wilder\zelda\modes\item_tracker\config\item_tracker.yaml
2019-04-02 19:10:18,340 : INFO : ConfigProcessor : Loading config from file C:\Users\Wilder\zelda\modes\item_tracker\config\item_tracker.yaml.
2019-04-02 19:10:18,341 : DEBUG : YAML File Interface : Loading file: C:\Users\Wilder\zelda\modes\item_tracker\config\item_tracker.yaml
2019-04-02 19:10:18,410 : ERROR : asyncio : Exception in callback EventManager._async_handler_done(<QueuedEvent>)(<Task finishe...column 1\'',)>) at c:\users\wilder\appdata\local\programs\python\python36\lib\site-packages\mpf\core\events.py:96
handle: <Handle EventManager._async_handler_done(<QueuedEvent>)(<Task finishe...column 1\'',)>) at c:\users\wilder\appdata\local\programs\python\python36\lib\site-packages\mpf\core\events.py:96>
Traceback (most recent call last):
  File "c:\users\wilder\appdata\local\programs\python\python36\lib\site-packages\mpf\file_interfaces\yaml_interface.py", line 198, in load
    config = self.process(f)
  File "c:\users\wilder\appdata\local\programs\python\python36\lib\site-packages\mpf\file_interfaces\yaml_interface.py", line 224, in process
    return yaml.load(data_string, Loader=MpfLoader)
  File "c:\users\wilder\appdata\local\programs\python\python36\lib\site-packages\ruamel\yaml\main.py", line 639, in load
    return loader._constructor.get_single_data()  # type: ignore
  File "c:\users\wilder\appdata\local\programs\python\python36\lib\site-packages\ruamel\yaml\constructor.py", line 104, in get_single_data
    return self.construct_document(node)
  File "c:\users\wilder\appdata\local\programs\python\python36\lib\site-packages\ruamel\yaml\constructor.py", line 114, in construct_document
    for dummy in generator:
  File "c:\users\wilder\appdata\local\programs\python\python36\lib\site-packages\ruamel\yaml\constructor.py", line 611, in construct_yaml_map
    value = self.construct_mapping(node)
  File "c:\users\wilder\appdata\local\programs\python\python36\lib\site-packages\mpf\file_interfaces\yaml_interface.py", line 135, in construct_mapping
    format(key, key_node.start_mark))
KeyError: 'Key "show_player" was defined multiple times in config   in "C:\\Users\\Wilder\\zelda\\modes\\item_tracker\\config\\item_tracker.yaml", line 161, column 1'

During handling of the above exception, another exception occurred:

Traceback (most recent call last):
  File "c:\users\wilder\appdata\local\programs\python\python36\lib\asyncio\events.py", line 145, in _run
    self._callback(*self._args)
  File "c:\users\wilder\appdata\local\programs\python\python36\lib\site-packages\mpf\core\events.py", line 99, in _async_handler_done
    future.result()
  File "c:\users\wilder\appdata\local\programs\python\python36\lib\site-packages\mpf\core\mode_controller.py", line 117, in load_modes
    self.machine.modes[mode] = self._load_mode(mode)
  File "c:\users\wilder\appdata\local\programs\python\python36\lib\site-packages\mpf\core\mode_controller.py", line 266, in _load_mode
    config = self._load_mode_config(mode_string)
  File "c:\users\wilder\appdata\local\programs\python\python36\lib\site-packages\mpf\core\mode_controller.py", line 184, in _load_mode_config
    store_to_cache=self.machine.options['create_config_cache'])
  File "c:\users\wilder\appdata\local\programs\python\python36\lib\site-packages\mpf\core\config_processor.py", line 112, in load_config_files_with_cache
    ignore_unknown_sections)
  File "c:\users\wilder\appdata\local\programs\python\python36\lib\site-packages\mpf\core\config_processor.py", line 132, in _load_config_file_and_return_loaded_files
    config = FileManager.load(filename, expected_version_str, True)
  File "c:\users\wilder\appdata\local\programs\python\python36\lib\site-packages\mpf\core\file_manager.py", line 99, in load
    return interface.load(file, verify_version, halt_on_error)
  File "c:\users\wilder\appdata\local\programs\python\python36\lib\site-packages\mpf\file_interfaces\yaml_interface.py", line 212, in load
    raise ValueError(msg)
ValueError: Error found in file C:\Users\Wilder\zelda\modes\item_tracker\config\item_tracker.yaml: 'Key "show_player" was defined multiple times in config   in "C:\\Users\\Wilder\\zelda\\modes\\item_tracker\\config\\item_tracker.yaml", line 161, column 1'
2019-04-02 19:10:18,416 : INFO : Machine : Starting the main run loop.
2019-04-02 19:10:18,416 : INFO : Machine : Shutting down...
2019-04-02 19:10:18,417 : INFO : EventManager : Event: ======'shutdown'====== Args={}
2019-04-02 19:10:18,419 : ERROR : FAST : Stop called on serial connection \\.\COM12
2019-04-02 19:10:18,420 : ERROR : FAST : Stop called on serial connection \\.\COM11
2019-04-02 19:10:18,745 : ERROR : root : Error found in file C:\Users\Wilder\zelda\modes\item_tracker\config\item_tracker.yaml: 'Key "show_player" was defined multiple times in config   in "C:\\Users\\Wilder\\zelda\\modes\\item_tracker\\config\\item_tracker.yaml", line 161, column 1'
Traceback (most recent call last):
  File "c:\users\wilder\appdata\local\programs\python\python36\lib\site-packages\mpf\file_interfaces\yaml_interface.py", line 198, in load
    config = self.process(f)
  File "c:\users\wilder\appdata\local\programs\python\python36\lib\site-packages\mpf\file_interfaces\yaml_interface.py", line 224, in process
    return yaml.load(data_string, Loader=MpfLoader)
  File "c:\users\wilder\appdata\local\programs\python\python36\lib\site-packages\ruamel\yaml\main.py", line 639, in load
    return loader._constructor.get_single_data()  # type: ignore
  File "c:\users\wilder\appdata\local\programs\python\python36\lib\site-packages\ruamel\yaml\constructor.py", line 104, in get_single_data
    return self.construct_document(node)
  File "c:\users\wilder\appdata\local\programs\python\python36\lib\site-packages\ruamel\yaml\constructor.py", line 114, in construct_document
    for dummy in generator:
  File "c:\users\wilder\appdata\local\programs\python\python36\lib\site-packages\ruamel\yaml\constructor.py", line 611, in construct_yaml_map
    value = self.construct_mapping(node)
  File "c:\users\wilder\appdata\local\programs\python\python36\lib\site-packages\mpf\file_interfaces\yaml_interface.py", line 135, in construct_mapping
    format(key, key_node.start_mark))
KeyError: 'Key "show_player" was defined multiple times in config   in "C:\\Users\\Wilder\\zelda\\modes\\item_tracker\\config\\item_tracker.yaml", line 161, column 1'

During handling of the above exception, another exception occurred:

Traceback (most recent call last):
  File "c:\users\wilder\appdata\local\programs\python\python36\lib\site-packages\mpf\commands\game.py", line 220, in __init__
    MachineController(mpf_path, machine_path, vars(self.args)).run()
  File "c:\users\wilder\appdata\local\programs\python\python36\lib\site-packages\mpf\core\machine.py", line 709, in run
    self._run_loop()
  File "c:\users\wilder\appdata\local\programs\python\python36\lib\site-packages\mpf\core\machine.py", line 769, in _run_loop
    raise self._exception['exception']
  File "c:\users\wilder\appdata\local\programs\python\python36\lib\asyncio\events.py", line 145, in _run
    self._callback(*self._args)
  File "c:\users\wilder\appdata\local\programs\python\python36\lib\site-packages\mpf\core\events.py", line 99, in _async_handler_done
    future.result()
  File "c:\users\wilder\appdata\local\programs\python\python36\lib\site-packages\mpf\core\mode_controller.py", line 117, in load_modes
    self.machine.modes[mode] = self._load_mode(mode)
  File "c:\users\wilder\appdata\local\programs\python\python36\lib\site-packages\mpf\core\mode_controller.py", line 266, in _load_mode
    config = self._load_mode_config(mode_string)
  File "c:\users\wilder\appdata\local\programs\python\python36\lib\site-packages\mpf\core\mode_controller.py", line 184, in _load_mode_config
    store_to_cache=self.machine.options['create_config_cache'])
  File "c:\users\wilder\appdata\local\programs\python\python36\lib\site-packages\mpf\core\config_processor.py", line 112, in load_config_files_with_cache
    ignore_unknown_sections)
  File "c:\users\wilder\appdata\local\programs\python\python36\lib\site-packages\mpf\core\config_processor.py", line 132, in _load_config_file_and_return_loaded_files
    config = FileManager.load(filename, expected_version_str, True)
  File "c:\users\wilder\appdata\local\programs\python\python36\lib\site-packages\mpf\core\file_manager.py", line 99, in load
    return interface.load(file, verify_version, halt_on_error)
  File "c:\users\wilder\appdata\local\programs\python\python36\lib\site-packages\mpf\file_interfaces\yaml_interface.py", line 212, in load
    raise ValueError(msg)
ValueError: Error found in file C:\Users\Wilder\zelda\modes\item_tracker\config\item_tracker.yaml: 'Key "show_player" was defined multiple times in config   in "C:\\Users\\Wilder\\zelda\\modes\\item_tracker\\config\\item_tracker.yaml", line 161, column 1'
